Workbook

Sheet Week  1
A1: Weekly Issued (Buffer Stock POMI)- POH 1
A2: Mnth | B2: 45992
A3: Week | B3: I
A4: No. | B4: Nama Barang | C4: Satuan | D4: Stock Awal | E4: Tanggal Buffer Stock | F4: Jumlah | G4: 45991 | I4: 45992 | K4: 45993 | M4: 45994 | O4: 45995 | Q4: 45996 | S4: 45997 | U4: Ending Stock | V4: KATEGORI
G5: Lokasi | H5: Jumlah | I5: Lokasi | J5: Jumlah | K5: Lokasi | L5: Jumlah | M5: Lokasi | N5: Jumlah | O5: Lokasi | P5: Jumlah | Q5: Lokasi | R5: Jumlah | S5: Lokasi | T5: Jumlah
A6: 1 | B6: AC Compressor 1 PK, PANASONIC R 22 | C6: Unit | D6: ='[1]Week (4)'!U6 | U6: =D6+F6+-(H6+J6+L6+N6+P6+R6+T6) | V6: AC
A7: =A6+1 | B7: AC Compressor 1,5 PK, PANASONIC R 22 | C7: Unit | D7: ='[1]Week (4)'!U7 | U7: =D7+F7+-(H7+J7+L7+N7+P7+R7+T7) | V7: AC
A8: =A7+1 | B8: AC Compressor 2 PK, PANASONIC | C8: Unit | D8: ='[1]Week (4)'!U8 | U8: =D8+F8+-(H8+J8+L8+N8+P8+R8+T8) | V8: AC
A9: =A8+1 | B9: AC Compressor 3 PK, PANASONIC | C9: Unit | D9: ='[1]Week (4)'!U9 | U9: =D9+F9+-(H9+J9+L9+N9+P9+R9+T9) | V9: AC
A10: =A9+1 | B10: AC Compressor 1 PK, PANASONIC R 32 | C10: Unit | D10: ='[1]Week (4)'!U10 | U10: =D10+F10+-(H10+J10+L10+N10+P10+R10+T10) | V10: AC
A11: =A10+1 | B11: AC Compressor 1,5 PK, PANASONIC R 32 | C11: Unit | D11: ='[1]Week (4)'!U11 | U11: =D11+F11+-(H11+J11+L11+N11+P11+R11+T11) | V11: AC
A12: =A11+1 | B12: Amplas NO 1 | C12: Lbr | D12: ='[1]Week (4)'!U12 | U12: =D12+F12+-(H12+J12+L12+N12+P12+R12+T12) | V12: CONSUMABLE
A13: =A12+1 | B13: Amplas NO 180 | C13: Lbr | D13: ='[1]Week (4)'!U13 | U13: =D13+F13+-(H13+J13+L13+N13+P13+R13+T13) | V13: CONSUMABLE
A14: =A13+1 | B14: Avur bak cuci piring | C14: pcs | D14: ='[1]Week (4)'!U14 | U14: =D14+F14+-(H14+J14+L14+N14+P14+R14+T14) | V14: SANITARY
A15: =A14+1 | B15: RESIBON CUTTING WHEEL | C15: Lbr | D15: ='[1]Week (4)'!U15 | K15: Parkir genset | L15: 2 | O15: Parkir sisi genset | P15: 4 | U15: =D15+F15+-(H15+J15+L15+N15+P15+R15+T15) | V15: CONSUMABLE
A16: =A15+1 | B16: RESIBON GRINDING WHEEL | C16: Lbr | D16: ='[1]Week (4)'!U16 | U16: =D16+F16+-(H16+J16+L16+N16+P16+R16+T16) | V16: CONSUMABLE
A17: =A16+1 | B17: Ball Valve 1/2" ONDA Kuningan | C17: Pcs | D17: ='[1]Week (4)'!U17 | U17: =D17+F17+-(H17+J17+L17+N17+P17+R17+T17) | V17: VALVE AND PIPE
A18: =A17+1 | B18: Ball Valve 3/4" ONDA Kuningan | C18: Pcs | D18: ='[1]Week (4)'!U18 | U18: =D18+F18+-(H18+J18+L18+N18+P18+R18+T18) | V18: VALVE AND PIPE
A19: =A18+1 | B19: BATTERY ALKALINE AA | C19: PCS | D19: ='[1]Week (4)'!U19 | U19: =D19+F19+-(H19+J19+L19+N19+P19+R19+T19) | V19: CONSUMABLE
A20: =A19+1 | B20: BATTERY ALKALINE AAA | C20: PCS | D20: ='[1]Week (4)'!U20 | U20: =D20+F20+-(H20+J20+L20+N20+P20+R20+T20) | V20: CONSUMABLE
A21: =A20+1 | B21: BATTERY KERING 6 VOLT | C21: PCS | D21: ='[1]Week (4)'!U21 | U21: =D21+F21+-(H21+J21+L21+N21+P21+R21+T21) | V21: CONSUMABLE
A22: =A21+1 | B22: Battery Kotak 9 Volt | C22: PCS | D22: ='[1]Week (4)'!U22 | U22: =D22+F22+-(H22+J22+L22+N22+P22+R22+T22) | V22: CONSUMABLE
A23: =A22+1 | B23: Baut Dipan | C23: PCS | D23: ='[1]Week (4)'!U23 | U23: =D23+F23+-(H23+J23+L23+N23+P23+R23+T23) | V23: CIVIL
A24: =A23+1 | B24: BATTERY ABC BESAR | C24: PCS | D24: ='[1]Week (4)'!U24 | U24: =D24+F24+-(H24+J24+L24+N24+P24+R24+T24) | V24: CONSUMABLE
A25: =A24+1 | B25: BEARING 608 ZZ | C25: Pcs | D25: ='[1]Week (4)'!U25 | U25: =D25+F25+-(H25+J25+L25+N25+P25+R25+T25) | V25: MECHANICAL
A26: =A25+1 | B26: Bearing 6202-2Z, SKF | C26: PCS | D26: ='[1]Week (4)'!U26 | U26: =D26+F26+-(H26+J26+L26+N26+P26+R26+T26) | V26: MECHANICAL
A27: =A26+1 | B27: BEARING 6203 ZZ | C27: Pcs | D27: ='[1]Week (4)'!U27 | U27: =D27+F27+-(H27+J27+L27+N27+P27+R27+T27) | V27: MECHANICAL
... A40: =A39+1 | B40: Capacitor 40µf | C40: PCS | D40: ='[1]Week (4)'!U40 | U40: =D40+F40+-(H40+J40+L40+N40+P40+R40+T40) | V40: AC
A41: =A40+1 | B41: Capacitor 35µf | C41: PCS | D41: ='[1]Week (4)'!U41 | K41: Sulawesi 15 | L41: 1 | U41: =D41+F41+-(H41+J41+L41+N41+P41+R41+T41) | V41: AC
A42: =A41+1 | B42: Capacitor 50 µf | C42: PCS | D42: ='[1]Week (4)'!U42 | U42: =D42+F42+-(H42+J42+L42+N42+P42+R42+T42) | V42: AC
A43: =A42+1 | B43: Capacitor AC 25 µf | C43: PCS | D43: ='[1]Week (4)'!U43 | U43: =D43+F43+-(H43+J43+L43+N43+P43+R43+T43) | V43: AC
A44: =A43+1 | B44: Capacitor Ceiling Fan 5 Cable | C44: PCS | D44: ='[1]Week (4)'!U44 | U44: =D44+F44+-(H44+J44+L44+N44+P44+R44+T44) | V44: ELECTRICAL
A45: =A44+1 | B45: Capacitor Washing Machine 12 µf | C45: PCS | D45: ='[1]Week (4)'!U45 | U45: =D45+F45+-(H45+J45+L45+N45+P45+R45+T45) | V45: ELECTRICAL
A46: =A45+1 | B46: Capacitor 60 µf | C46: PCS | D46: ='[1]Week (4)'!U46 | U46: =D46+F46+-(H46+J46+L46+N46+P46+R46+T46) | V46: AC
A47: =A46+1 | B47: CAT DULUX CATYLAC INVERNES 25KG | C47: Pail | D47: ='[1]Week (4)'!U47 | U47: =D47+F47+-(H47+J47+L47+N47+P47+R47+T47) | V47: CIVIL
A48: =A47+1 | B48: CAT DULUX CATYLAC INVERNES 5 KG | C48: GLN | D48: ='[1]Week (4)'!U48 | U48: =D48+F48+-(H48+J48+L48+N48+P48+R48+T48) | V48: CIVIL
A49: =A48+1 | B49: CAT DULUX MORNING STAR 2,5 LTR | C49: GLN | D49: ='[1]Week (4)'!U49 | U49: =D49+F49+-(H49+J49+L49+N49+P49+R49+T49) | V49: CIVIL
A50: =A49+1 | B50: CAT JAVA EXTERIOR | C50: PAIL | D50: ='[1]Week (4)'!U50 | U50: =D50+F50+-(H50+J50+L50+N50+P50+R50+T50) | V50: CIVIL
A51: =A50+1 | B51: CAT JAVA INTERIOR NO. 31 | C51: PAIL | D51: ='[1]Week (4)'!U51 | U51: =D51+F51+-(H51+J51+L51+N51+P51+R51+T51) | V51: CIVIL
A52: =A51+1 | B52: CAT JAVA INTERIOR NO. 32 | C52: PAIL | D52: ='[1]Week (4)'!U52 | U52: =D52+F52+-(H52+J52+L52+N52+P52+R52+T52) | V52: CIVIL
...

Sheet Week  (2)
A1: Weekly Issued (Buffer Stock POMI)- POH 1
A2: Mnth | B2: 45992
A3: Week | B3: II
A4: No. | B4: Nama Barang | C4: Satuan | D4: Stock Awal | E4: Tanggal Buffer Stock | F4: Jumlah | G4: 45998 | I4: 45999 | K4: 46000 | M4: 46001 | O4: 46002 | Q4: 46003 | S4: 46004 | U4: Ending Stock | V4: KATEGORI
G5: Lokasi | H5: Jumlah | I5: Lokasi | J5: Jumlah | K5: Lokasi | L5: Jumlah | M5: Lokasi | N5: Jumlah | O5: Lokasi | P5: Jumlah | Q5: Lokasi | R5: Jumlah | S5: Lokasi | T5: Jumlah
A6: 1 | B6: AC Compressor 1 PK, PANASONIC R 22 | C6: Unit | D6: ='Week 1'!U6 | U6: =D6+F6+-(H6+J6+L6+N6+P6+R6+T6) | V6: AC
A7: =A6+1 | B7: AC Compressor 1,5 PK, PANASONIC R 22 | C7: Unit | D7: ='Week 1'!U7 | U7: =D7+F7+-(H7+J7+L7+N7+P7+R7+T7) | V7: AC
A8: =A7+1 | B8: AC Compressor 2 PK, PANASONIC | C8: Unit | D8: ='Week 1'!U8 | U8: =D8+F8+-(H8+J8+L8+N8+P8+R8+T8) | V8: AC
A9: =A8+1 | B9: AC Compressor 3 PK, PANASONIC | C9: Unit | D9: ='Week 1'!U9 | U9: =D9+F9+-(H9+J9+L9+N9+P9+R9+T9) | V9: AC
A10: =A9+1 | B10: AC Compressor 1 PK, PANASONIC R 32 | C10: Unit | D10: ='Week 1'!U10 | U10: =D10+F10+-(H10+J10+L10+N10+P10+R10+T10) | V10: AC
A11: =A10+1 | B11: AC Compressor 1,5 PK, PANASONIC R 32 | C11: Unit | D11: ='Week 1'!U11 | U11: =D11+F11+-(H11+J11+L11+N11+P11+R11+T11) | V11: AC
A12: =A11+1 | B12: Amplas NO 1 | C12: Lbr | D12: ='Week 1'!U12 | U12: =D12+F12+-(H12+J12+L12+N12+P12+R12+T12) | V12: CONSUMABLE
A13: =A12+1 | B13: Amplas NO 180 | C13: Lbr | D13: ='Week 1'!U13 | U13: =D13+F13+-(H13+J13+L13+N13+P13+R13+T13) | V13: CONSUMABLE
A14: =A13+1 | B14: Avur bak cuci piring | C14: pcs | D14: ='Week 1'!U14 | U14: =D14+F14+-(H14+J14+L14+N14+P14+R14+T14) | V14: SANITARY
A15: =A14+1 | B15: RESIBON CUTTING WHEEL | C15: Lbr | D15: ='Week 1'!U15 | U15: =D15+F15+-(H15+J15+L15+N15+P15+R15+T15) | V15: CONSUMABLE
A16: =A15+1 | B16: RESIBON GRINDING WHEEL | C16: Lbr | D16: ='Week 1'!U16 | U16: =D16+F16+-(H16+J16+L16+N16+P16+R16+T16) | V16: CONSUMABLE
A17: =A16+1 | B17: Ball Valve 1/2" ONDA Kuningan | C17: Pcs | D17: ='Week 1'!U17 | U17: =D17+F17+-(H17+J17+L17+N17+P17+R17+T17) | V17: VALVE AND PIPE
A18: =A17+1 | B18: Ball Valve 3/4" ONDA Kuningan | C18: Pcs | D18: ='Week 1'!U18 | U18: =D18+F18+-(H18+J18+L18+N18+P18+R18+T18) | V18: VALVE AND PIPE
A19: =A18+1 | B19: BATTERY ALKALINE AA | C19: PCS | D19: ='Week 1'!U19 | U19: =D19+F19+-(H19+J19+L19+N19+P19+R19+T19) | V19: CONSUMABLE
A20: =A19+1 | B20: BATTERY ALKALINE AAA | C20: PCS | D20: ='Week 1'!U20 | M20: gym=2, Sumatera 10=2 | N20: =2+2 | U20: =D20+F20+-(H20+J20+L20+N20+P20+R20+T20) | V20: CONSUMABLE
A21: =A20+1 | B21: BATTERY KERING 6 VOLT | C21: PCS | D21: ='Week 1'!U21 | U21: =D21+F21+-(H21+J21+L21+N21+P21+R21+T21) | V21: CONSUMABLE
A22: =A21+1 | B22: Battery Kotak 9 Volt | C22: PCS | D22: ='Week 1'!U22 | U22: =D22+F22+-(H22+J22+L22+N22+P22+R22+T22) | V22: CONSUMABLE
A23: =A22+1 | B23: Baut Dipan | C23: PCS | D23: ='Week 1'!U23 | U23: =D23+F23+-(H23+J23+L23+N23+P23+R23+T23) | V23: CIVIL
A24: =A23+1 | B24: BATTERY ABC BESAR | C24: PCS | D24: ='Week 1'!U24 | U24: =D24+F24+-(H24+J24+L24+N24+P24+R24+T24) | V24: CONSUMABLE
A25: =A24+1 | B25: BEARING 608 ZZ | C25: Pcs | D25: ='Week 1'!U25 | U25: =D25+F25+-(H25+J25+L25+N25+P25+R25+T25) | V25: MECHANICAL
A26: =A25+1 | B26: Bearing 6202-2Z, SKF | C26: PCS | D26: ='Week 1'!U26 | U26: =D26+F26+-(H26+J26+L26+N26+P26+R26+T26) | V26: MECHANICAL
A27: =A26+1 | B27: BEARING 6203 ZZ | C27: Pcs | D27: ='Week 1'!U27 | U27: =D27+F27+-(H27+J27+L27+N27+P27+R27+T27) | V27: MECHANICAL
A28: =A27+1 | B28: Bearing 6303 | C28: Pcs | D28: ='Week 1'!U28 | U28: =D28+F28+-(H28+J28+L28+N28+P28+R28+T28) | V28: MECHANICAL
A29: =A28+1 | B29: Bearing 6304 ZZ | C29: PCS | D29: ='Week 1'!U29 | U29: =D29+F29+-(H29+J29+L29+N29+P29+R29+T29) | V29: MECHANICAL
A30: =A29+1 | B30: Bearing 6305 SKF | C30: PCS | D30: ='Week 1'!U30 | U30: =D30+F30+-(H30+J30+L30+N30+P30+R30+T30) | V30: MECHANICAL
A31: =A30+1 | B31: Bearing SKF 6306 ZZ | C31: PCS | D31: ='Week 1'!U31 | U31: =D31+F31+-(H31+J31+L31+N31+P31+R31+T31) | V31: MECHANICAL
A32: =A31+1 | B32: Bearing SKF 6307 ZZ | C32: PCS | D32: ='Week 1'!U32 | U32: =D32+F32+-(H32+J32+L32+N32+P32+R32+T32) | V32: MECHANICAL
... A82: =A81+1 | B82: Elbow Drat Dalam 20 x 1/2" hdpe | C82: PCS | D82: ='Week 1'!U82 | U82: =D82+F82+-(H82+J82+L82+N82+P82+R82+T82) | V82: VALVE AND PIPE
A83: =A82+1 | B83: Elbow PVC AW 1" | C83: Pcs | D83: ='Week 1'!U83 | K83: Madura 6 | L83: 1 | U83: =D83+F83+-(H83+J83+L83+N83+P83+R83+T83) | V83: VALVE AND PIPE
A84: =A83+1 | B84: Elbow PVC AW 1/2" | C84: Pcs | D84: ='Week 1'!U84 | U84: =D84+F84+-(H84+J84+L84+N84+P84+R84+T84) | V84: VALVE AND PIPE
A85: 80 | B85: Elbow PVC AW 2" | C85: Pcs | D85: ='Week 1'!U85 | U85: =D85+F85+-(H85+J85+L85+N85+P85+R85+T85) | V85: VALVE AND PIPE
A86: =A85+1 | B86: ELCB 2P, 25A SCHNEIDER | C86: PCS | D86: ='Week 1'!U86 | U86: =D86+F86+-(H86+J86+L86+N86+P86+R86+T86) | V86: ELECTRICAL
A87: =A86+1 | B87: ELCB 2P, 30A SCHNEIDER | C87: PCS | D87: ='Week 1'!U87 | U87: =D87+F87+-(H87+J87+L87+N87+P87+R87+T87) | V87: ELECTRICAL
A88: =A87+1 | B88: ELCB 2P, 40A SCHNEIDER | C88: PCS | D88: ='Week 1'!U88 | U88: =D88+F88+-(H88+J88+L88+N88+P88+R88+T88) | V88: ELECTRICAL
A89: =A88+1 | B89: ELCB 2P, 63A SCHNEIDER | C89: PCS | D89: ='Week 1'!U89 | U89: =D89+F89+-(H89+J89+L89+N89+P89+R89+T89) | V89: ELECTRICAL
...

Sheet Week  (3)
A1: Weekly Issued (Buffer Stock POMI)- POH 1
A2: Mnth | B2: 45992
A3: Week | B3: III
A4: No. | B4: Nama Barang | C4: Satuan | D4: Stock Awal | E4: Tanggal Buffer Stock | F4: Jumlah | G4: 46005 | I4: 46006 | K4: 46007 | M4: 46008 | O4: 46009 | Q4: 46010 | S4: 46011 | U4: Ending Stock | V4: KATEGORI
G5: Lokasi | H5: Jumlah | I5: Lokasi | J5: Jumlah | K5: Lokasi | L5: Jumlah | M5: Lokasi | N5: Jumlah | O5: Lokasi | P5: Jumlah | Q5: Lokasi | R5: Jumlah | S5: Lokasi | T5: Jumlah
A6: 1 | B6: AC Compressor 1 PK, PANASONIC R 22 | C6: Unit | D6: ='Week (2)'!U6 | U6: =D6+F6+-(H6+J6+L6+N6+P6+R6+T6) | V6: AC
A7: =A6+1 | B7: AC Compressor 1,5 PK, PANASONIC R 22 | C7: Unit | D7: ='Week (2)'!U7 | U7: =D7+F7+-(H7+J7+L7+N7+P7+R7+T7) | V7: AC
A8: =A7+1 | B8: AC Compressor 2 PK, PANASONIC | C8: Unit | D8: ='Week (2)'!U8 | U8: =D8+F8+-(H8+J8+L8+N8+P8+R8+T8) | V8: AC
A9: =A8+1 | B9: AC Compressor 3 PK, PANASONIC | C9: Unit | D9: ='Week (2)'!U9 | U9: =D9+F9+-(H9+J9+L9+N9+P9+R9+T9) | V9: AC
A10: =A9+1 | B10: AC Compressor 1 PK, PANASONIC R 32 | C10: Unit | D10: ='Week (2)'!U10 | U10: =D10+F10+-(H10+J10+L10+N10+P10+R10+T10) | V10: AC
A11: =A10+1 | B11: AC Compressor 1,5 PK, PANASONIC R 32 | C11: Unit | D11: ='Week (2)'!U11 | U11: =D11+F11+-(H11+J11+L11+N11+P11+R11+T11) | V11: AC
A12: =A11+1 | B12: Amplas NO 1 | C12: Lbr | D12: ='Week (2)'!U12 | U12: =D12+F12+-(H12+J12+L12+N12+P12+R12+T12) | V12: CONSUMABLE
A13: =A12+1 | B13: Amplas NO 180 | C13: Lbr | D13: ='Week (2)'!U13 | I13: Lap basket | J13: 1 | U13: =D13+F13+-(H13+J13+L13+N13+P13+R13+T13) | V13: CONSUMABLE
A14: =A13+1 | B14: Avur bak cuci piring | C14: pcs | D14: ='Week (2)'!U14 | U14: =D14+F14+-(H14+J14+L14+N14+P14+R14+T14) | V14: SANITARY
A15: =A14+1 | B15: RESIBON CUTTING WHEEL | C15: Lbr | D15: ='Week (2)'!U15 | Q15: Reserviir tank | R15: 1 | U15: =D15+F15+-(H15+J15+L15+N15+P15+R15+T15) | V15: CONSUMABLE
A16: =A15+1 | B16: RESIBON GRINDING WHEEL | C16: Lbr | D16: ='Week (2)'!U16 | U16: =D16+F16+-(H16+J16+L16+N16+P16+R16+T16) | V16: CONSUMABLE
A17: =A16+1 | B17: Ball Valve 1/2" ONDA Kuningan | C17: Pcs | D17: ='Week (2)'!U17 | U17: =D17+F17+-(H17+J17+L17+N17+P17+R17+T17) | V17: VALVE AND PIPE
A18: =A17+1 | B18: Ball Valve 3/4" ONDA Kuningan | C18: Pcs | D18: ='Week (2)'!U18 | U18: =D18+F18+-(H18+J18+L18+N18+P18+R18+T18) | V18: VALVE AND PIPE
A19: =A18+1 | B19: BATTERY ALKALINE AA | C19: PCS | D19: ='Week (2)'!U19 | U19: =D19+F19+-(H19+J19+L19+N19+P19+R19+T19) | V19: CONSUMABLE
A20: =A19+1 | B20: BATTERY ALKALINE AAA | C20: PCS | D20: ='Week (2)'!U20 | U20: =D20+F20+-(H20+J20+L20+N20+P20+R20+T20) | V20: CONSUMABLE
A21: =A20+1 | B21: BATTERY KERING 6 VOLT | C21: PCS | D21: ='Week (2)'!U21 | U21: =D21+F21+-(H21+J21+L21+N21+P21+R21+T21) | V21: CONSUMABLE
A22: =A21+1 | B22: Battery Kotak 9 Volt | C22: PCS | D22: ='Week (2)'!U22 | U22: =D22+F22+-(H22+J22+L22+N22+P22+R22+T22) | V22: CONSUMABLE
A23: =A22+1 | B23: Baut Dipan | C23: PCS | D23: ='Week (2)'!U23 | U23: =D23+F23+-(H23+J23+L23+N23+P23+R23+T23) | V23: CIVIL
A24: =A23+1 | B24: BATTERY ABC BESAR | C24: PCS | D24: ='Week (2)'!U24 | U24: =D24+F24+-(H24+J24+L24+N24+P24+R24+T24) | V24: CONSUMABLE
A25: =A24+1 | B25: BEARING 608 ZZ | C25: Pcs | D25: ='Week (2)'!U25 | U25: =D25+F25+-(H25+J25+L25+N25+P25+R25+T25) | V25: MECHANICAL
A26: =A25+1 | B26: Bearing 6202-2Z, SKF | C26: PCS | D26: ='Week (2)'!U26 | U26: =D26+F26+-(H26+J26+L26+N26+P26+R26+T26) | V26: MECHANICAL
A27: =A26+1 | B27: BEARING 6203 ZZ | C27: Pcs | D27: ='Week (2)'!U27 | U27: =D27+F27+-(H27+J27+L27+N27+P27+R27+T27) | V27: MECHANICAL
... A55: =A54+1 | B55: Cat Pylox Merah | C55: Btl | D55: ='Week (2)'!U55 | U55: =D55+F55+-(H55+J55+L55+N55+P55+R55+T55) | V55: CIVIL
A56: =A55+1 | B56: Cat Pylox Putih | C56: Btl | D56: ='Week (2)'!U56 | M56: POOL Gazebo | N56: 1 | U56: =D56+F56+-(H56+J56+L56+N56+P56+R56+T56) | V56: CIVIL
A57: =A56+1 | B57: Cat Zynchromate | C57: Kg | D57: ='Week (2)'!U57 | U57: =D57+F57+-(H57+J57+L57+N57+P57+R57+T57) | V57: CIVIL
A58: =A57+1 | B58: Cat Avian Putih | C58: Kg | D58: ='Week (2)'!U58 | U58: =D58+F58+-(H58+J58+L58+N58+P58+R58+T58) | V58: CIVIL
A59: =A58+1 | B59: Semen, Gresik | C59: SACK | D59: ='Week (2)'!U59 | M59: Sumatera 16 | N59: =4/40 | Q59: Sumatera 10 | R59: =6/40 | U59: =D59+F59+-(H59+J59+L59+N59+P59+R59+T59) | V59: CIVIL
A60: =A59+1 | B60: Semen Putih | C60: Kg | D60: ='Week (2)'!U60 | U60: =D60+F60+-(H60+J60+L60+N60+P60+R60+T60) | V60: CIVIL
A61: =A60+1 | B61: Ceramic size 20x25 PUTIH | C61: DUs | D61: ='Week (2)'!U61 | U61: =D61+F61+-(H61+J61+L61+N61+P61+R61+T61) | V61: CIVIL
A62: =A61+1 | B62: Ceramic size 30x30 | C62: Dus | D62: ='Week (2)'!U62 | U62: =D62+F62+-(H62+J62+L62+N62+P62+R62+T62) | V62: CIVIL
A63: =A62+1 | B63: Contactor LC1D09M7, Scheider | C63: PCS | D63: ='Week (2)'!U63 | U63: =D63+F63+-(H63+J63+L63+N63+P63+R63+T63) | V63: ELECTRICAL
A64: =A63+1 | B64: Contactor LC1D12M7, Scheider | C64: PCS | D64: ='Week (2)'!U64 | U64: =D64+F64+-(H64+J64+L64+N64+P64+R64+T64) | V64: ELECTRICAL
A65: =A64+1 | B65: Contactor LC1D18M7, Scheider | C65: PCS | D65: ='Week (2)'!U65 | U65: =D65+F65+-(H65+J65+L65+N65+P65+R65+T65) | V65: ELECTRICAL
A66: =A65+1 | B66: Contactor LC1D25M7, Scheider | C66: PCS | D66: ='Week (2)'!U66 | U66: =D66+F66+-(H66+J66+L66+N66+P66+R66+T66) | V66: ELECTRICAL
A67: =A66+1 | B67: Contactor LC1D32M7, Scheider | C67: PCS | D67: ='Week (2)'!U67 | U67: =D67+F67+-(H67+J67+L67+N67+P67+R67+T67) | V67: ELECTRICAL
...

Sheet Week  (4)
A1: Weekly Issued (Buffer Stock POMI)- POH 1
A2: Mnth | B2: 45992
A3: Week | B3: IV
A4: No. | B4: Nama Barang | C4: Satuan | D4: Stock Awal | E4: Tanggal Buffer Stock | F4: Jumlah | G4: 46011 | I4: 46012 | K4: 46013 | M4: 46014 | O4: 46015 | Q4: 46016 | S4: 46017 | U4: Ending Stock | V4: KATEGORI
G5: Lokasi | H5: Jumlah | I5: Lokasi | J5: Jumlah | K5: Lokasi | L5: Jumlah | M5: Lokasi | N5: Jumlah | O5: Lokasi | P5: Jumlah | Q5: Lokasi | R5: Jumlah | S5: Lokasi | T5: Jumlah
A6: 1 | B6: AC Compressor 1 PK, PANASONIC R 22 | C6: Unit | D6: ='Week (3)'!U6 | U6: =D6+F6+-(H6+J6+L6+N6+P6+R6+T6) | V6: AC
A7: =A6+1 | B7: AC Compressor 1,5 PK, PANASONIC R 22 | C7: Unit | D7: ='Week (3)'!U7 | U7: =D7+F7+-(H7+J7+L7+N7+P7+R7+T7) | V7: AC
A8: =A7+1 | B8: AC Compressor 2 PK, PANASONIC | C8: Unit | D8: ='Week (3)'!U8 | U8: =D8+F8+-(H8+J8+L8+N8+P8+R8+T8) | V8: AC
A9: =A8+1 | B9: AC Compressor 3 PK, PANASONIC | C9: Unit | D9: ='Week (3)'!U9 | U9: =D9+F9+-(H9+J9+L9+N9+P9+R9+T9) | V9: AC
A10: =A9+1 | B10: AC Compressor 1 PK, PANASONIC R 32 | C10: Unit | D10: ='Week (3)'!U10 | U10: =D10+F10+-(H10+J10+L10+N10+P10+R10+T10) | V10: AC
A11: =A10+1 | B11: AC Compressor 1,5 PK, PANASONIC R 32 | C11: Unit | D11: ='Week (3)'!U11 | U11: =D11+F11+-(H11+J11+L11+N11+P11+R11+T11) | V11: AC
A12: =A11+1 | B12: Amplas NO 1 | C12: Lbr | D12: ='Week (3)'!U12 | U12: =D12+F12+-(H12+J12+L12+N12+P12+R12+T12) | V12: CONSUMABLE
A13: =A12+1 | B13: Amplas NO 180 | C13: Lbr | D13: ='Week (3)'!U13 | O13: Rechall | P13: 1 | U13: =D13+F13+-(H13+J13+L13+N13+P13+R13+T13) | V13: CONSUMABLE
A14: =A13+1 | B14: Avur bak cuci piring | C14: pcs | D14: ='Week (3)'!U14 | U14: =D14+F14+-(H14+J14+L14+N14+P14+R14+T14) | V14: SANITARY
A15: =A14+1 | B15: RESIBON CUTTING WHEEL | C15: Lbr | D15: ='Week (3)'!U15 | U15: =D15+F15+-(H15+J15+L15+N15+P15+R15+T15) | V15: CONSUMABLE
A16: =A15+1 | B16: RESIBON GRINDING WHEEL | C16: Lbr | D16: ='Week (3)'!U16 | U16: =D16+F16+-(H16+J16+L16+N16+P16+R16+T16) | V16: CONSUMABLE
A17: =A16+1 | B17: Ball Valve 1/2" ONDA Kuningan | C17: Pcs | D17: ='Week (3)'!U17 | U17: =D17+F17+-(H17+J17+L17+N17+P17+R17+T17) | V17: VALVE AND PIPE
A18: =A17+1 | B18: Ball Valve 3/4" ONDA Kuningan | C18: Pcs | D18: ='Week (3)'!U18 | U18: =D18+F18+-(H18+J18+L18+N18+P18+R18+T18) | V18: VALVE AND PIPE
A19: =A18+1 | B19: BATTERY ALKALINE AA | C19: PCS | D19: ='Week (3)'!U19 | U19: =D19+F19+-(H19+J19+L19+N19+P19+R19+T19) | V19: CONSUMABLE
A20: =A19+1 | B20: BATTERY ALKALINE AAA | C20: PCS | D20: ='Week (3)'!U20 | M20: IT Room | N20: 1 | U20: =D20+F20+-(H20+J20+L20+N20+P20+R20+T20) | V20: CONSUMABLE
A21: =A20+1 | B21: BATTERY KERING 6 VOLT | C21: PCS | D21: ='Week (3)'!U21 | U21: =D21+F21+-(H21+J21+L21+N21+P21+R21+T21) | V21: CONSUMABLE
A22: =A21+1 | B22: Battery Kotak 9 Volt | C22: PCS | D22: ='Week (3)'!U22 | S22: Jawa 9 | T22: 1 | U22: =D22+F22+-(H22+J22+L22+N22+P22+R22+T22) | V22: CONSUMABLE
A23: =A22+1 | B23: Baut Dipan | C23: PCS | D23: ='Week (3)'!U23 | U23: =D23+F23+-(H23+J23+L23+N23+P23+R23+T23) | V23: CIVIL
A24: =A23+1 | B24: BATTERY ABC BESAR | C24: PCS | D24: ='Week (3)'!U24 | U24: =D24+F24+-(H24+J24+L24+N24+P24+R24+T24) | V24: CONSUMABLE
A25: =A24+1 | B25: BEARING 608 ZZ | C25: Pcs | D25: ='Week (3)'!U25 | U25: =D25+F25+-(H25+J25+L25+N25+P25+R25+T25) | V25: MECHANICAL
A26: =A25+1 | B26: Bearing 6202-2Z, SKF | C26: PCS | D26: ='Week (3)'!U26 | O26: Lombok 6 | P26: 2 | U26: =D26+F26+-(H26+J26+L26+N26+P26+R26+T26) | V26: MECHANICAL
A27: =A26+1 | B27: BEARING 6203 ZZ | C27: Pcs | D27: ='Week (3)'!U27 | U27: =D27+F27+-(H27+J27+L27+N27+P27+R27+T27) | V27: MECHANICAL
A28: =A27+1 | B28: Bearing 6303 | C28: Pcs | D28: ='Week (3)'!U28 | U28: =D28+F28+-(H28+J28+L28+N28+P28+R28+T28) | V28: MECHANICAL
A29: =A28+1 | B29: Bearing 6304 ZZ | C29: PCS | D29: ='Week (3)'!U29 | U29: =D29+F29+-(H29+J29+L29+N29+P29+R29+T29) | V29: MECHANICAL
A30: =A29+1 | B30: Bearing 6305 SKF | C30: PCS | D30: ='Week (3)'!U30 | U30: =D30+F30+-(H30+J30+L30+N30+P30+R30+T30) | V30: MECHANICAL
A31: =A30+1 | B31: Bearing SKF 6306 ZZ | C31: PCS | D31: ='Week (3)'!U31 | U31: =D31+F31+-(H31+J31+L31+N31+P31+R31+T31) | V31: MECHANICAL
A32: =A31+1 | B32: Bearing SKF 6307 ZZ | C32: PCS | D32: ='Week (3)'!U32 | U32: =D32+F32+-(H32+J32+L32+N32+P32+R32+T32) | V32: MECHANICAL
A33: =A32+1 | B33: Bearing SKF 6309 / C3 | C33: PCS | D33: ='Week (3)'!U33 | U33: =D33+F33+-(H33+J33+L33+N33+P33+R33+T33) | V33: MECHANICAL
A34: =A33+1 | B34: Bearing SKF 63305 ZZ | C34: PCS | D34: ='Week (3)'!U34 | U34: =D34+F34+-(H34+J34+L34+N34+P34+R34+T34) | V34: MECHANICAL
A35: =A34+1 | B35: Bearing SKF 6309 C3 | C35: PCS | D35: ='Week (3)'!U35 | U35: =D35+F35+-(H35+J35+L35+N35+P35+R35+T35) | V35: MECHANICAL
A36: =A35+1 | B36: Bulb Lamp 25 W, A 35 Clear Philips, | C36: PCS | D36: ='Week (3)'!U36 | U36: =D36+F36+-(H36+J36+L36+N36+P36+R36+T36) | V36: LAMP
A37: =A36+1 | B37: Bulb Lamp 40 W, B 35 Clear Philips, E 14 ( cooker hood ) | C37: PCS | D37: ='Week (3)'!U37 | U37: =D37+F37+-(H37+J37+L37+N37+P37+R37+T37) | V37: LAMP
A38: =A37+1 | B38: Capacitor 2,5µf + 2 µf | C38: PCS | D38: ='Week (3)'!U38 | U38: =D38+F38+-(H38+J38+L38+N38+P38+R38+T38) | V38: ELECTRICAL
A39: =A38+1 | B39: Capacitor 30µf | C39: PCS | D39: ='Week (3)'!U39 | S39: Sulawesi 11 | T39: 1 | U39: =D39+F39+-(H39+J39+L39+N39+P39+R39+T39) | V39: AC
A40: =A39+1 | B40: Capacitor 40µf | C40: PCS | D40: ='Week (3)'!U40 | U40: =D40+F40+-(H40+J40+L40+N40+P40+R40+T40) | V40: AC
...

Sheet Week  (5)
A1: Weekly Issued (Buffer Stock POMI)- POH 1
A2: Mnth | B2: 45992
A3: Week | B3: V
A4: No. | B4: Nama Barang | C4: Satuan | D4: Stock Awal | E4: Tanggal Buffer Stock | F4: Jumlah | G4: 46018 | I4: 46019 | K4: 46020 | M4: 46021 | O4: 46022 | Q4: 46023 | S4: 46024 | U4: Ending Stock | V4: KATEGORI
G5: Lokasi | H5: Jumlah | I5: Lokasi | J5: Jumlah | K5: Lokasi | L5: Jumlah | M5: Lokasi | N5: Jumlah | O5: Lokasi | P5: Jumlah | Q5: Lokasi | R5: Jumlah | S5: Lokasi | T5: Jumlah
A6: 1 | B6: AC Compressor 1 PK, PANASONIC R 22 | C6: Unit | D6: ='Week (4)'!U6 | U6: =D6+F6+-(H6+J6+L6+N6+P6+R6+T6) | V6: AC
A7: =A6+1 | B7: AC Compressor 1,5 PK, PANASONIC R 22 | C7: Unit | D7: ='Week (4)'!U7 | U7: =D7+F7+-(H7+J7+L7+N7+P7+R7+T7) | V7: AC
A8: =A7+1 | B8: AC Compressor 2 PK, PANASONIC | C8: Unit | D8: ='Week (4)'!U8 | U8: =D8+F8+-(H8+J8+L8+N8+P8+R8+T8) | V8: AC
A9: =A8+1 | B9: AC Compressor 3 PK, PANASONIC | C9: Unit | D9: ='Week (4)'!U9 | U9: =D9+F9+-(H9+J9+L9+N9+P9+R9+T9) | V9: AC
A10: =A9+1 | B10: AC Compressor 1 PK, PANASONIC R 32 | C10: Unit | D10: ='Week (4)'!U10 | U10: =D10+F10+-(H10+J10+L10+N10+P10+R10+T10) | V10: AC
A11: =A10+1 | B11: AC Compressor 1,5 PK, PANASONIC R 32 | C11: Unit | D11: ='Week (4)'!U11 | U11: =D11+F11+-(H11+J11+L11+N11+P11+R11+T11) | V11: AC
A12: =A11+1 | B12: Amplas NO 1 | C12: Lbr | D12: ='Week (4)'!U12 | O12: Lombok 18 | P12: 1 | U12: =D12+F12+-(H12+J12+L12+N12+P12+R12+T12) | V12: CONSUMABLE
A13: =A12+1 | B13: Amplas NO 180 | C13: Lbr | D13: ='Week (4)'!U13 | K13: Sulawesi 4 | L13: 1 | U13: =D13+F13+-(H13+J13+L13+N13+P13+R13+T13) | V13: CONSUMABLE
A14: =A13+1 | B14: Avur bak cuci piring | C14: pcs | D14: ='Week (4)'!U14 | U14: =D14+F14+-(H14+J14+L14+N14+P14+R14+T14) | V14: SANITARY
A15: =A14+1 | B15: RESIBON CUTTING WHEEL | C15: Lbr | D15: ='Week (4)'!U15 | U15: =D15+F15+-(H15+J15+L15+N15+P15+R15+T15) | V15: CONSUMABLE
A16: =A15+1 | B16: RESIBON GRINDING WHEEL | C16: Lbr | D16: ='Week (4)'!U16 | U16: =D16+F16+-(H16+J16+L16+N16+P16+R16+T16) | V16: CONSUMABLE
A17: =A16+1 | B17: Ball Valve 1/2" ONDA Kuningan | C17: Pcs | D17: ='Week (4)'!U17 | U17: =D17+F17+-(H17+J17+L17+N17+P17+R17+T17) | V17: VALVE AND PIPE
A18: =A17+1 | B18: Ball Valve 3/4" ONDA Kuningan | C18: Pcs | D18: ='Week (4)'!U18 | U18: =D18+F18+-(H18+J18+L18+N18+P18+R18+T18) | V18: VALVE AND PIPE
A19: =A18+1 | B19: BATTERY ALKALINE AA | C19: PCS | D19: ='Week (4)'!U19 | U19: =D19+F19+-(H19+J19+L19+N19+P19+R19+T19) | V19: CONSUMABLE
A20: =A19+1 | B20: BATTERY ALKALINE AAA | C20: PCS | D20: ='Week (4)'!U20 | U20: =D20+F20+-(H20+J20+L20+N20+P20+R20+T20) | V20: CONSUMABLE
A21: =A20+1 | B21: BATTERY KERING 6 VOLT | C21: PCS | D21: ='Week (4)'!U21 | U21: =D21+F21+-(H21+J21+L21+N21+P21+R21+T21) | V21: CONSUMABLE
A22: =A21+1 | B22: Battery Kotak 9 Volt | C22: PCS | D22: ='Week (4)'!U22 | U22: =D22+F22+-(H22+J22+L22+N22+P22+R22+T22) | V22: CONSUMABLE
A23: =A22+1 | B23: Baut Dipan | C23: PCS | D23: ='Week (4)'!U23 | U23: =D23+F23+-(H23+J23+L23+N23+P23+R23+T23) | V23: CIVIL
A24: =A23+1 | B24: BATTERY ABC BESAR | C24: PCS | D24: ='Week (4)'!U24 | U24: =D24+F24+-(H24+J24+L24+N24+P24+R24+T24) | V24: CONSUMABLE
A25: =A24+1 | B25: BEARING 608 ZZ | C25: Pcs | D25: ='Week (4)'!U25 | U25: =D25+F25+-(H25+J25+L25+N25+P25+R25+T25) | V25: MECHANICAL
... A40: =A39+1 | B40: Capacitor 40µf | C40: PCS | D40: ='Week (4)'!U40 | U40: =D40+F40+-(H40+J40+L40+N40+P40+R40+T40) | V40: AC
A41: =A40+1 | B41: Capacitor 35µf | C41: PCS | D41: ='Week (4)'!U41 | M41: ISS office | N41: 1 | U41: =D41+F41+-(H41+J41+L41+N41+P41+R41+T41) | V41: AC
A42: =A41+1 | B42: Capacitor 50 µf | C42: PCS | D42: ='Week (4)'!U42 | U42: =D42+F42+-(H42+J42+L42+N42+P42+R42+T42) | V42: AC
A43: =A42+1 | B43: Capacitor AC 25 µf | C43: PCS | D43: ='Week (4)'!U43 | U43: =D43+F43+-(H43+J43+L43+N43+P43+R43+T43) | V43: AC
A44: =A43+1 | B44: Capacitor Ceiling Fan 5 Cable | C44: PCS | D44: ='Week (4)'!U44 | U44: =D44+F44+-(H44+J44+L44+N44+P44+R44+T44) | V44: ELECTRICAL
A45: =A44+1 | B45: Capacitor Washing Machine 12 µf | C45: PCS | D45: ='Week (4)'!U45 | U45: =D45+F45+-(H45+J45+L45+N45+P45+R45+T45) | V45: ELECTRICAL
A46: =A45+1 | B46: Capacitor 60 µf | C46: PCS | D46: ='Week (4)'!U46 | U46: =D46+F46+-(H46+J46+L46+N46+P46+R46+T46) | V46: AC
A47: =A46+1 | B47: CAT DULUX CATYLAC INVERNES 25KG | C47: Pail | D47: ='Week (4)'!U47 | U47: =D47+F47+-(H47+J47+L47+N47+P47+R47+T47) | V47: CIVIL
A48: =A47+1 | B48: CAT DULUX CATYLAC INVERNES 5 KG | C48: GLN | D48: ='Week (4)'!U48 | U48: =D48+F48+-(H48+J48+L48+N48+P48+R48+T48) | V48: CIVIL
A49: =A48+1 | B49: CAT DULUX MORNING STAR 2,5 LTR | C49: GLN | D49: ='Week (4)'!U49 | U49: =D49+F49+-(H49+J49+L49+N49+P49+R49+T49) | V49: CIVIL
A50: =A49+1 | B50: CAT JAVA EXTERIOR | C50: PAIL | D50: ='Week (4)'!U50 | U50: =D50+F50+-(H50+J50+L50+N50+P50+R50+T50) | V50: CIVIL
A51: =A50+1 | B51: CAT JAVA INTERIOR NO. 31 | C51: PAIL | D51: ='Week (4)'!U51 | U51: =D51+F51+-(H51+J51+L51+N51+P51+R51+T51) | V51: CIVIL
A52: =A51+1 | B52: CAT JAVA INTERIOR NO. 32 | C52: PAIL | D52: ='Week (4)'!U52 | U52: =D52+F52+-(H52+J52+L52+N52+P52+R52+T52) | V52: CIVIL
A53: =A52+1 | B53: Cat NIPPE 2000 No.012 ( CHAMONIK) | C53: KG | D53: ='Week (4)'!U53 | U53: =D53+F53+-(H53+J53+L53+N53+P53+R53+T53) | V53: CIVIL
... A58: =A57+1 | B58: Cat Avian Putih | C58: Kg | D58: ='Week (4)'!U58 | U58: =D58+F58+-(H58+J58+L58+N58+P58+R58+T58) | V58: CIVIL
...
